<sdf version='1.6'>
  <world name='default'>
    <light name='sun' type='directional'>
      <cast_shadows>1</cast_shadows>
      <pose frame=''>0 0 10 0 -0 0</pose>
      <diffuse>0.8 0.8 0.8 1</diffuse>
      <specular>0.2 0.2 0.2 1</specular>
      <attenuation>
        <range>1000</range>
        <constant>0.9</constant>
        <linear>0.01</linear>
        <quadratic>0.001</quadratic>
      </attenuation>
      <direction>-0.5 0.1 -0.9</direction>
    </light>
    <model name='ground_plane'>
      <static>1</static>
      <link name='link'>
        <collision name='collision'>
          <geometry>
            <plane>
              <normal>0 0 1</normal>
              <size>100 100</size>
            </plane>
          </geometry>
          <surface>
            <friction>
              <ode>
                <mu>100</mu>
                <mu2>50</mu2>
              </ode>
              <torsional>
                <ode/>
              </torsional>
            </friction>
            <contact>
              <ode/>
            </contact>
            <bounce/>
          </surface>
          <max_contacts>10</max_contacts>
        </collision>
        <visual name='visual'>
          <cast_shadows>0</cast_shadows>
          <geometry>
            <plane>
              <normal>0 0 1</normal>
              <size>100 100</size>
            </plane>
          </geometry>
          <material>
            <script>
              <uri>file://media/materials/scripts/gazebo.material</uri>
              <name>Gazebo/Grey</name>
            </script>
          </material>
        </visual>
        <self_collide>0</self_collide>
        <kinematic>0</kinematic>
      </link>
    </model>
    <gravity>0 0 -9.8</gravity>
    <magnetic_field>6e-06 2.3e-05 -4.2e-05</magnetic_field>
    <atmosphere type='adiabatic'/>
    <physics name='default_physics' default='0' type='ode'>
      <max_step_size>0.001</max_step_size>
      <real_time_factor>1</real_time_factor>
      <real_time_update_rate>1000</real_time_update_rate>
    </physics>
    <scene>
      <ambient>0.4 0.4 0.4 1</ambient>
      <background>0.7 0.7 0.7 1</background>
      <shadows>1</shadows>
    </scene>
    <spherical_coordinates>
      <surface_model>EARTH_WGS84</surface_model>
      <latitude_deg>0</latitude_deg>
      <longitude_deg>0</longitude_deg>
      <elevation>0</elevation>
      <heading_deg>0</heading_deg>
    </spherical_coordinates>
    <model name='robot_description'>
      <link name='base_footprint'>
        <pose frame=''>0 0 0 0 -0 0</pose>
        <inertial>
          <pose frame=''>-0.155979 3.7e-05 0.283742 0 -0 0</pose>
          <mass>5.05301</mass>
          <inertia>
            <ixx>0.106781</ixx>
            <ixy>0.000106036</ixy>
            <ixz>0.0448605</ixz>
            <iyy>0.127669</iyy>
            <iyz>-0.000243696</iyz>
            <izz>0.0308872</izz>
          </inertia>
        </inertial>
        <collision name='base_footprint_fixed_joint_lump__base_link_collision'>
          <pose frame=''>0 0 0.17 0 -0 0</pose>
          <geometry>
            <mesh>
              <scale>1 1 1</scale>
              <uri>/home/marins/catkin_ws/src/nuric_wheelchair_model_02/meshes/wheelchair_base_seat.dae</uri>
            </mesh>
          </geometry>
          <max_contacts>10</max_contacts>
          <surface>
            <contact>
              <ode/>
            </contact>
            <bounce/>
            <friction>
              <torsional>
                <ode/>
              </torsional>
              <ode/>
            </friction>
          </surface>
        </collision>
        <collision name='base_footprint_fixed_joint_lump__camera_link_collision_1'>
          <pose frame=''>-0.72 0 1.58 0 0.35 0</pose>
          <geometry>
            <box>
              <size>0.073 0.276 0.072</size>
            </box>
          </geometry>
          <surface>
            <contact>
              <ode/>
            </contact>
            <friction>
              <ode/>
              <torsional>
                <ode/>
              </torsional>
            </friction>
            <bounce/>
          </surface>
          <max_contacts>10</max_contacts>
        </collision>
        <collision name='base_footprint_fixed_joint_lump__laser_joint_collision_2'>
          <pose frame=''>-0.55 0 1.17 0 0.2 0</pose>
          <geometry>
            <box>
              <size>0.1 0.1 0.1</size>
            </box>
          </geometry>
          <surface>
            <contact>
              <ode/>
            </contact>
            <friction>
              <ode/>
              <torsional>
                <ode/>
              </torsional>
            </friction>
            <bounce/>
          </surface>
          <max_contacts>10</max_contacts>
        </collision>
        <visual name='base_footprint_visual'>
          <pose frame=''>0 0 0 0 -0 0</pose>
          <geometry>
            <box>
              <size>0.01 0.01 0.01</size>
            </box>
          </geometry>
        </visual>
        <visual name='base_footprint_fixed_joint_lump__base_link_visual_1'>
          <pose frame=''>0 0 0.17 0 -0 0</pose>
          <geometry>
            <mesh>
              <scale>1 1 1</scale>
              <uri>/home/marins/catkin_ws/src/nuric_wheelchair_model_02/meshes/wheelchair_base_seat.dae</uri>
            </mesh>
          </geometry>
        </visual>
        <velocity_decay/>
        <velocity_decay/>
        <sensor name='camera' type='depth'>
          <always_on>1</always_on>
          <visualize>1</visualize>
          <camera name='__default__'>
            <horizontal_fov>1.047</horizontal_fov>
            <image>
              <width>640</width>
              <height>480</height>
              <format>R8G8B8</format>
            </image>
            <depth_camera>
              <output>depths</output>
            </depth_camera>
            <clip>
              <near>0.1</near>
              <far>6</far>
            </clip>
          </camera>
          <plugin name='kinect_camera_controller' filename='libgazebo_ros_openni_kinect.so'>
            <baseline>0.1</baseline>
            <alwaysOn>true</alwaysOn>
            <updateRate>20.0</updateRate>
            <cameraName>camera</cameraName>
            <imageTopicName>/camera/rgb/image_raw</imageTopicName>
            <cameraInfoTopicName>/camera/rgb/camera_info</cameraInfoTopicName>
            <depthImageTopicName>/camera/depth/image_raw</depthImageTopicName>
            <depthImageCameraInfoTopicName>/camera/depth/camera_info</depthImageCameraInfoTopicName>
            <pointCloudTopicName>/camera/depth/points</pointCloudTopicName>
            <frameName>camera_rgb_optical_frame</frameName>
            <pointCloudCutoff>0.5</pointCloudCutoff>
            <distortionK1>0.0</distortionK1>
            <distortionK2>0.0</distortionK2>
            <distortionK3>0.0</distortionK3>
            <distortionT1>0.0</distortionT1>
            <distortionT2>0.0</distortionT2>
            <CxPrime>0</CxPrime>
            <Cx>0</Cx>
            <Cy>0</Cy>
            <focalLength>0</focalLength>
            <hackBaseline>0.07</hackBaseline>
            <robotNamespace>/</robotNamespace>
          </plugin>
          <pose frame=''>-0.72 0 1.58 0 0.35 0</pose>
        </sensor>
        <gravity>1</gravity>
        <velocity_decay/>
        <sensor name='camera1' type='camera'>
          <update_rate>20</update_rate>
          <camera name='head'>
            <horizontal_fov>1.79626</horizontal_fov>
            <image>
              <width>1200</width>
              <height>600</height>
              <format>R8G8B8</format>
            </image>
            <clip>
              <near>0.02</near>
              <far>30</far>
            </clip>
            <noise>
              <type>gaussian</type>
              <mean>0</mean>
              <stddev>0.002</stddev>
            </noise>
          </camera>
          <plugin name='camera_controller' filename='libgazebo_ros_camera.so'>
            <alwaysOn>true</alwaysOn>
            <updateRate>0.0</updateRate>
            <cameraName>rrbot/camera1</cameraName>
            <imageTopicName>image_raw</imageTopicName>
            <cameraInfoTopicName>camera_info</cameraInfoTopicName>
            <frameName>camera_link</frameName>
            <hackBaseline>0.07</hackBaseline>
            <distortionK1>0.0</distortionK1>
            <distortionK2>0.0</distortionK2>
            <distortionK3>0.0</distortionK3>
            <distortionT1>0.0</distortionT1>
            <distortionT2>0.0</distortionT2>
            <robotNamespace>/</robotNamespace>
          </plugin>
          <pose frame=''>-0.55 0 1.17 0 0.2 0</pose>
        </sensor>
        <self_collide>0</self_collide>
        <kinematic>0</kinematic>
      </link>
      <link name='left_caster_hub_link'>
        <pose frame=''>-0.58 0.19 0.1 0 -0 0</pose>
        <inertial>
          <pose frame=''>-0.043126 0.030993 0.053064 0 -0 0</pose>
          <mass>0.015</mass>
          <inertia>
            <ixx>0.001</ixx>
            <ixy>0</ixy>
            <ixz>0</ixz>
            <iyy>0.001</iyy>
            <iyz>0</iyz>
            <izz>0.001</izz>
          </inertia>
        </inertial>
        <collision name='left_caster_hub_link_collision'>
          <pose frame=''>0 0 0 0 -0 0</pose>
          <geometry>
            <mesh>
              <scale>1 1 1</scale>
              <uri>/home/marins/catkin_ws/src/nuric_wheelchair_model_02/meshes/caster_hub_left.dae</uri>
            </mesh>
          </geometry>
          <max_contacts>10</max_contacts>
          <surface>
            <contact>
              <ode/>
            </contact>
            <bounce/>
            <friction>
              <torsional>
                <ode/>
              </torsional>
              <ode/>
            </friction>
          </surface>
        </collision>
        <visual name='left_caster_hub_link_visual'>
          <pose frame=''>0 0 0 0 -0 0</pose>
          <geometry>
            <mesh>
              <scale>1 1 1</scale>
              <uri>/home/marins/catkin_ws/src/nuric_wheelchair_model_02/meshes/caster_hub_left.dae</uri>
            </mesh>
          </geometry>
        </visual>
        <gravity>1</gravity>
        <velocity_decay/>
        <self_collide>0</self_collide>
        <kinematic>0</kinematic>
      </link>
      <joint name='base_left_caster_hub_joint' type='revolute'>
        <child>left_caster_hub_link</child>
        <parent>base_footprint</parent>
        <axis>
          <xyz>0 0 1</xyz>
          <limit>
            <lower>-1e+16</lower>
            <upper>1e+16</upper>
          </limit>
          <dynamics>
            <damping>0</damping>
            <friction>0</friction>
            <spring_reference>0</spring_reference>
            <spring_stiffness>0</spring_stiffness>
          </dynamics>
          <use_parent_model_frame>1</use_parent_model_frame>
        </axis>
      </joint>
      <link name='left_caster_wheel_link'>
        <pose frame=''>-0.64 0.19 0.1 0 -0 0</pose>
        <inertial>
          <pose frame=''>0 0 0 0 -0 0</pose>
          <mass>0.07</mass>
          <inertia>
            <ixx>0.001</ixx>
            <ixy>0</ixy>
            <ixz>0</ixz>
            <iyy>0.001</iyy>
            <iyz>0</iyz>
            <izz>0.001</izz>
          </inertia>
        </inertial>
        <collision name='left_caster_wheel_link_collision'>
          <pose frame=''>0 0 0 1.5708 -0 0</pose>
          <geometry>
            <cylinder>
              <length>0.038</length>
              <radius>0.1</radius>
            </cylinder>
          </geometry>
          <surface>
            <contact>
              <ode>
                <kp>1000</kp>
                <kd>1000</kd>
              </ode>
            </contact>
            <friction>
              <ode>
                <mu>100</mu>
                <mu2>100</mu2>
              </ode>
              <torsional>
                <ode/>
              </torsional>
            </friction>
            <bounce/>
          </surface>
          <max_contacts>10</max_contacts>
        </collision>
        <visual name='left_caster_wheel_link_visual'>
          <pose frame=''>0 0 0 0 -0 0</pose>
          <geometry>
            <mesh>
              <scale>1 1 1</scale>
              <uri>/home/marins/catkin_ws/src/nuric_wheelchair_model_02/meshes/caster_wheel.dae</uri>
            </mesh>
          </geometry>
          <material>
            <script>
              <uri>__default__</uri>
              <name>__default__</name>
            </script>
          </material>
        </visual>
        <gravity>1</gravity>
        <velocity_decay/>
        <self_collide>0</self_collide>
        <kinematic>0</kinematic>
      </link>
      <joint name='left_caster_hub_left_caster_wheel_joint' type='revolute'>
        <child>left_caster_wheel_link</child>
        <parent>left_caster_hub_link</parent>
        <axis>
          <xyz>0 1 0</xyz>
          <limit>
            <lower>-1e+16</lower>
            <upper>1e+16</upper>
          </limit>
          <dynamics>
            <damping>0</damping>
            <friction>0.02</friction>
            <spring_reference>0</spring_reference>
            <spring_stiffness>0</spring_stiffness>
          </dynamics>
          <use_parent_model_frame>1</use_parent_model_frame>
        </axis>
      </joint>
      <link name='left_front_wheel_link'>
        <pose frame=''>0 0.27 0.17 0 -0 0</pose>
        <inertial>
          <pose frame=''>0 0 0 0 -0 0</pose>
          <mass>0.5</mass>
          <inertia>
            <ixx>0.005</ixx>
            <ixy>0</ixy>
            <ixz>0</ixz>
            <iyy>0.005</iyy>
            <iyz>0</iyz>
            <izz>0.005</izz>
          </inertia>
        </inertial>
        <collision name='left_front_wheel_link_collision'>
          <pose frame=''>0 0 0 1.5708 -0 0</pose>
          <geometry>
            <cylinder>
              <length>0.07</length>
              <radius>0.17</radius>
            </cylinder>
          </geometry>
          <surface>
            <contact>
              <ode>
                <kp>1000</kp>
                <kd>1000</kd>
              </ode>
            </contact>
            <friction>
              <ode>
                <mu>100</mu>
                <mu2>100</mu2>
              </ode>
              <torsional>
                <ode/>
              </torsional>
            </friction>
            <bounce/>
          </surface>
          <max_contacts>10</max_contacts>
        </collision>
        <visual name='left_front_wheel_link_visual'>
          <pose frame=''>0 0 0 0 -0 0</pose>
          <geometry>
            <mesh>
              <scale>1 1 1</scale>
              <uri>/home/marins/catkin_ws/src/nuric_wheelchair_model_02/meshes/front_wheel.dae</uri>
            </mesh>
          </geometry>
          <material>
            <script>
              <uri>__default__</uri>
              <name>__default__</name>
            </script>
          </material>
        </visual>
        <gravity>1</gravity>
        <velocity_decay/>
        <self_collide>0</self_collide>
        <kinematic>0</kinematic>
      </link>
      <joint name='base_left_front_wheel_joint' type='revolute'>
        <child>left_front_wheel_link</child>
        <parent>base_footprint</parent>
        <axis>
          <xyz>0 1 0</xyz>
          <limit>
            <lower>-1e+16</lower>
            <upper>1e+16</upper>
          </limit>
          <dynamics>
            <damping>0</damping>
            <friction>0.05</friction>
            <spring_reference>0</spring_reference>
            <spring_stiffness>0</spring_stiffness>
          </dynamics>
          <use_parent_model_frame>1</use_parent_model_frame>
        </axis>
      </joint>
      <link name='right_caster_hub_link'>
        <pose frame=''>-0.58 -0.19 0.1 0 -0 -3.14159</pose>
        <inertial>
          <pose frame=''>0.043126 0.030993 0.053064 0 -0 0</pose>
          <mass>0.015</mass>
          <inertia>
            <ixx>0.001</ixx>
            <ixy>0</ixy>
            <ixz>0</ixz>
            <iyy>0.001</iyy>
            <iyz>0</iyz>
            <izz>0.001</izz>
          </inertia>
        </inertial>
        <collision name='right_caster_hub_link_collision'>
          <pose frame=''>0 0 0 0 -0 0</pose>
          <geometry>
            <mesh>
              <scale>1 1 1</scale>
              <uri>/home/marins/catkin_ws/src/nuric_wheelchair_model_02/meshes/caster_hub_right.dae</uri>
            </mesh>
          </geometry>
          <max_contacts>10</max_contacts>
          <surface>
            <contact>
              <ode/>
            </contact>
            <bounce/>
            <friction>
              <torsional>
                <ode/>
              </torsional>
              <ode/>
            </friction>
          </surface>
        </collision>
        <visual name='right_caster_hub_link_visual'>
          <pose frame=''>0 0 0 0 -0 0</pose>
          <geometry>
            <mesh>
              <scale>1 1 1</scale>
              <uri>/home/marins/catkin_ws/src/nuric_wheelchair_model_02/meshes/caster_hub_right.dae</uri>
            </mesh>
          </geometry>
        </visual>
        <gravity>1</gravity>
        <velocity_decay/>
        <self_collide>0</self_collide>
        <kinematic>0</kinematic>
      </link>
      <joint name='base_right_caster_hub_joint' type='revolute'>
        <child>right_caster_hub_link</child>
        <parent>base_footprint</parent>
        <axis>
          <xyz>0 0 1</xyz>
          <limit>
            <lower>-1e+16</lower>
            <upper>1e+16</upper>
          </limit>
          <dynamics>
            <damping>0</damping>
            <friction>0</friction>
            <spring_reference>0</spring_reference>
            <spring_stiffness>0</spring_stiffness>
          </dynamics>
          <use_parent_model_frame>1</use_parent_model_frame>
        </axis>
      </joint>
      <link name='right_caster_wheel_link'>
        <pose frame=''>-0.64 -0.19 0.1 0 -0 -3.14159</pose>
        <inertial>
          <pose frame=''>0 0 0 0 -0 0</pose>
          <mass>0.07</mass>
          <inertia>
            <ixx>0.001</ixx>
            <ixy>0</ixy>
            <ixz>0</ixz>
            <iyy>0.001</iyy>
            <iyz>0</iyz>
            <izz>0.001</izz>
          </inertia>
        </inertial>
        <collision name='right_caster_wheel_link_collision'>
          <pose frame=''>0 0 0 1.5708 -0 0</pose>
          <geometry>
            <cylinder>
              <length>0.038</length>
              <radius>0.1</radius>
            </cylinder>
          </geometry>
          <surface>
            <contact>
              <ode>
                <kp>1000</kp>
                <kd>1000</kd>
              </ode>
            </contact>
            <friction>
              <ode>
                <mu>100</mu>
                <mu2>100</mu2>
              </ode>
              <torsional>
                <ode/>
              </torsional>
            </friction>
            <bounce/>
          </surface>
          <max_contacts>10</max_contacts>
        </collision>
        <visual name='right_caster_wheel_link_visual'>
          <pose frame=''>0 0 0 0 -0 0</pose>
          <geometry>
            <mesh>
              <scale>1 1 1</scale>
              <uri>/home/marins/catkin_ws/src/nuric_wheelchair_model_02/meshes/caster_wheel.dae</uri>
            </mesh>
          </geometry>
          <material>
            <script>
              <uri>__default__</uri>
              <name>__default__</name>
            </script>
          </material>
        </visual>
        <gravity>1</gravity>
        <velocity_decay/>
        <self_collide>0</self_collide>
        <kinematic>0</kinematic>
      </link>
      <joint name='right_caster_hub_right_caster_wheel_joint' type='revolute'>
        <child>right_caster_wheel_link</child>
        <parent>right_caster_hub_link</parent>
        <axis>
          <xyz>0 -1 0</xyz>
          <limit>
            <lower>-1e+16</lower>
            <upper>1e+16</upper>
          </limit>
          <dynamics>
            <damping>0</damping>
            <friction>0.02</friction>
            <spring_reference>0</spring_reference>
            <spring_stiffness>0</spring_stiffness>
          </dynamics>
          <use_parent_model_frame>1</use_parent_model_frame>
        </axis>
      </joint>
      <link name='right_front_wheel_link'>
        <pose frame=''>0 -0.27 0.17 0 -0 0</pose>
        <inertial>
          <pose frame=''>0 0 0 0 -0 0</pose>
          <mass>0.5</mass>
          <inertia>
            <ixx>0.005</ixx>
            <ixy>0</ixy>
            <ixz>0</ixz>
            <iyy>0.005</iyy>
            <iyz>0</iyz>
            <izz>0.005</izz>
          </inertia>
        </inertial>
        <collision name='right_front_wheel_link_collision'>
          <pose frame=''>0 0 0 1.5708 -0 0</pose>
          <geometry>
            <cylinder>
              <length>0.07</length>
              <radius>0.17</radius>
            </cylinder>
          </geometry>
          <surface>
            <contact>
              <ode>
                <kp>1000</kp>
                <kd>1000</kd>
              </ode>
            </contact>
            <friction>
              <ode>
                <mu>100</mu>
                <mu2>100</mu2>
              </ode>
              <torsional>
                <ode/>
              </torsional>
            </friction>
            <bounce/>
          </surface>
          <max_contacts>10</max_contacts>
        </collision>
        <visual name='right_front_wheel_link_visual'>
          <pose frame=''>0 0 0 0 -0 0</pose>
          <geometry>
            <mesh>
              <scale>1 1 1</scale>
              <uri>/home/marins/catkin_ws/src/nuric_wheelchair_model_02/meshes/front_wheel.dae</uri>
            </mesh>
          </geometry>
          <material>
            <script>
              <uri>__default__</uri>
              <name>__default__</name>
            </script>
          </material>
        </visual>
        <gravity>1</gravity>
        <velocity_decay/>
        <self_collide>0</self_collide>
        <kinematic>0</kinematic>
      </link>
      <joint name='base_right_front_wheel_joint' type='revolute'>
        <child>right_front_wheel_link</child>
        <parent>base_footprint</parent>
        <axis>
          <xyz>0 1 0</xyz>
          <limit>
            <lower>-1e+16</lower>
            <upper>1e+16</upper>
          </limit>
          <dynamics>
            <damping>0</damping>
            <friction>0.05</friction>
            <spring_reference>0</spring_reference>
            <spring_stiffness>0</spring_stiffness>
          </dynamics>
          <use_parent_model_frame>1</use_parent_model_frame>
        </axis>
      </joint>
      <plugin name='gazebo_ros_control' filename='libgazebo_ros_control.so'>
        <robotNamespace>/</robotNamespace>
      </plugin>
      <plugin name='joint_state_publisher' filename='libgazebo_ros_joint_state_publisher.so'>
        <jointName>base_left_caster_hub_joint, base_right_caster_hub_joint, base_left_front_wheel_joint, base_right_front_wheel_joint, left_caster_hub_left_caster_wheel_joint, right_caster_hub_right_caster_wheel_joint</jointName>
        <updateRate>50.0</updateRate>
        <alwaysOn>true</alwaysOn>
        <robotNamespace>/</robotNamespace>
      </plugin>
      <static>0</static>
      <plugin name='differential_drive_controller' filename='libgazebo_ros_diff_drive.so'>
        <alwaysOn>true</alwaysOn>
        <updateRate>50</updateRate>
        <leftJoint>base_right_front_wheel_joint</leftJoint>
        <rightJoint>base_left_front_wheel_joint</rightJoint>
        <wheelSeparation>0.54</wheelSeparation>
        <wheelDiameter>0.34</wheelDiameter>
        <torque>100</torque>
        <commandTopic>cmd_vel</commandTopic>
        <odometryTopic>odom</odometryTopic>
        <odometryFrame>odom</odometryFrame>
        <robotBaseFrame>base_footprint</robotBaseFrame>
        <robotNamespace>/</robotNamespace>
      </plugin>
      <pose frame=''>0 0 0 0 -0 0</pose>
    </model>
    <model name='adaptada'>
      <pose frame=''>1.04989 -0.082902 0 0 -0 0</pose>
      <link name='Wall_0'>
        <collision name='Wall_0_Collision'>
          <geometry>
            <box>
              <size>6.25 0.15 2.5</size>
            </box>
          </geometry>
          <pose frame=''>0 0 1.25 0 -0 0</pose>
          <max_contacts>10</max_contacts>
          <surface>
            <contact>
              <ode/>
            </contact>
            <bounce/>
            <friction>
              <torsional>
                <ode/>
              </torsional>
              <ode/>
            </friction>
          </surface>
        </collision>
        <visual name='Wall_0_Visual'>
          <pose frame=''>0 0 1.25 0 -0 0</pose>
          <geometry>
            <box>
              <size>6.25 0.15 2.5</size>
            </box>
          </geometry>
          <material>
            <script>
              <uri>file://media/materials/scripts/gazebo.material</uri>
              <name>Gazebo/CeilingTiled</name>
            </script>
            <ambient>1 1 1 1</ambient>
          </material>
          <meta>
            <layer>0</layer>
          </meta>
        </visual>
        <pose frame=''>7.05 -1.35 0 0 -0 1.5708</pose>
        <self_collide>0</self_collide>
        <kinematic>0</kinematic>
      </link>
      <link name='Wall_1'>
        <pose frame=''>4.875 1.7 0 0 -0 3.14159</pose>
        <visual name='Wall_1_Visual_0'>
          <pose frame=''>-2.04113 0 1.25 0 -0 0</pose>
          <geometry>
            <box>
              <size>0.417739 0.15 2.5</size>
            </box>
          </geometry>
          <material>
            <script>
              <uri>file://media/materials/scripts/gazebo.material</uri>
              <name>Gazebo/Bricks</name>
            </script>
            <ambient>1 1 1 1</ambient>
          </material>
          <meta>
            <layer>0</layer>
          </meta>
        </visual>
        <collision name='Wall_1_Collision_0'>
          <geometry>
            <box>
              <size>0.417739 0.15 2.5</size>
            </box>
          </geometry>
          <pose frame=''>-2.04113 0 1.25 0 -0 0</pose>
          <max_contacts>10</max_contacts>
          <surface>
            <contact>
              <ode/>
            </contact>
            <bounce/>
            <friction>
              <torsional>
                <ode/>
              </torsional>
              <ode/>
            </friction>
          </surface>
        </collision>
        <visual name='Wall_1_Visual_1'>
          <pose frame=''>0.70887 0 1.25 0 -0 0</pose>
          <geometry>
            <box>
              <size>3.08226 0.15 2.5</size>
            </box>
          </geometry>
          <material>
            <script>
              <uri>file://media/materials/scripts/gazebo.material</uri>
              <name>Gazebo/Bricks</name>
            </script>
            <ambient>1 1 1 1</ambient>
          </material>
          <meta>
            <layer>0</layer>
          </meta>
        </visual>
        <collision name='Wall_1_Collision_1'>
          <geometry>
            <box>
              <size>3.08226 0.15 2.5</size>
            </box>
          </geometry>
          <pose frame=''>0.70887 0 1.25 0 -0 0</pose>
          <max_contacts>10</max_contacts>
          <surface>
            <contact>
              <ode/>
            </contact>
            <bounce/>
            <friction>
              <torsional>
                <ode/>
              </torsional>
              <ode/>
            </friction>
          </surface>
        </collision>
        <visual name='Wall_1_Visual_2'>
          <pose frame=''>-1.33226 0 2.25 0 -0 0</pose>
          <geometry>
            <box>
              <size>1 0.15 0.5</size>
            </box>
          </geometry>
          <material>
            <script>
              <uri>file://media/materials/scripts/gazebo.material</uri>
              <name>Gazebo/Bricks</name>
            </script>
            <ambient>1 1 1 1</ambient>
          </material>
          <meta>
            <layer>0</layer>
          </meta>
        </visual>
        <collision name='Wall_1_Collision_2'>
          <geometry>
            <box>
              <size>1 0.15 0.5</size>
            </box>
          </geometry>
          <pose frame=''>-1.33226 0 2.25 0 -0 0</pose>
          <max_contacts>10</max_contacts>
          <surface>
            <contact>
              <ode/>
            </contact>
            <bounce/>
            <friction>
              <torsional>
                <ode/>
              </torsional>
              <ode/>
            </friction>
          </surface>
        </collision>
        <self_collide>0</self_collide>
        <kinematic>0</kinematic>
      </link>
      <link name='Wall_11'>
        <collision name='Wall_11_Collision'>
          <geometry>
            <box>
              <size>2.75 0.15 2.5</size>
            </box>
          </geometry>
          <pose frame=''>0 0 1.25 0 -0 0</pose>
          <max_contacts>10</max_contacts>
          <surface>
            <contact>
              <ode/>
            </contact>
            <bounce/>
            <friction>
              <torsional>
                <ode/>
              </torsional>
              <ode/>
            </friction>
          </surface>
        </collision>
        <visual name='Wall_11_Visual'>
          <pose frame=''>0 0 1.25 0 -0 0</pose>
          <geometry>
            <box>
              <size>2.75 0.15 2.5</size>
            </box>
          </geometry>
          <material>
            <script>
              <uri>file://media/materials/scripts/gazebo.material</uri>
              <name>Gazebo/Wood</name>
            </script>
            <ambient>1 1 1 1</ambient>
          </material>
          <meta>
            <layer>0</layer>
          </meta>
        </visual>
        <pose frame=''>-4.09133 -0.927238 0 0 -0 0</pose>
        <self_collide>0</self_collide>
        <kinematic>0</kinematic>
      </link>
      <link name='Wall_12'>
        <pose frame=''>-2.79133 -2.60224 0 0 0 -1.5708</pose>
        <visual name='Wall_12_Visual_0'>
          <pose frame=''>-1.62181 0 1.25 0 -0 0</pose>
          <geometry>
            <box>
              <size>0.256373 0.15 2.5</size>
            </box>
          </geometry>
          <material>
            <script>
              <uri>file://media/materials/scripts/gazebo.material</uri>
              <name>Gazebo/Wood</name>
            </script>
            <ambient>1 1 1 1</ambient>
          </material>
          <meta>
            <layer>0</layer>
          </meta>
        </visual>
        <collision name='Wall_12_Collision_0'>
          <geometry>
            <box>
              <size>0.256373 0.15 2.5</size>
            </box>
          </geometry>
          <pose frame=''>-1.62181 0 1.25 0 -0 0</pose>
          <max_contacts>10</max_contacts>
          <surface>
            <contact>
              <ode/>
            </contact>
            <bounce/>
            <friction>
              <torsional>
                <ode/>
              </torsional>
              <ode/>
            </friction>
          </surface>
        </collision>
        <visual name='Wall_12_Visual_1'>
          <pose frame=''>0.628187 0 1.25 0 -0 0</pose>
          <geometry>
            <box>
              <size>2.24363 0.15 2.5</size>
            </box>
          </geometry>
          <material>
            <script>
              <uri>file://media/materials/scripts/gazebo.material</uri>
              <name>Gazebo/Wood</name>
            </script>
            <ambient>1 1 1 1</ambient>
          </material>
          <meta>
            <layer>0</layer>
          </meta>
        </visual>
        <collision name='Wall_12_Collision_1'>
          <geometry>
            <box>
              <size>2.24363 0.15 2.5</size>
            </box>
          </geometry>
          <pose frame=''>0.628187 0 1.25 0 -0 0</pose>
          <max_contacts>10</max_contacts>
          <surface>
            <contact>
              <ode/>
            </contact>
            <bounce/>
            <friction>
              <torsional>
                <ode/>
              </torsional>
              <ode/>
            </friction>
          </surface>
        </collision>
        <visual name='Wall_12_Visual_2'>
          <pose frame=''>-0.993627 0 2.25 0 -0 0</pose>
          <geometry>
            <box>
              <size>1 0.15 0.5</size>
            </box>
          </geometry>
          <material>
            <script>
              <uri>file://media/materials/scripts/gazebo.material</uri>
              <name>Gazebo/Wood</name>
            </script>
            <ambient>1 1 1 1</ambient>
          </material>
          <meta>
            <layer>0</layer>
          </meta>
        </visual>
        <collision name='Wall_12_Collision_2'>
          <geometry>
            <box>
              <size>1 0.15 0.5</size>
            </box>
          </geometry>
          <pose frame=''>-0.993627 0 2.25 0 -0 0</pose>
          <max_contacts>10</max_contacts>
          <surface>
            <contact>
              <ode/>
            </contact>
            <bounce/>
            <friction>
              <torsional>
                <ode/>
              </torsional>
              <ode/>
            </friction>
          </surface>
        </collision>
        <self_collide>0</self_collide>
        <kinematic>0</kinematic>
      </link>
      <link name='Wall_14'>
        <pose frame=''>2.67834 3.04275 0 0 0 -1.55466</pose>
        <visual name='Wall_14_Visual_0'>
          <pose frame=''>-1.33225 0 1.25 0 -0 0</pose>
          <geometry>
            <box>
              <size>0.171349 0.15 2.5</size>
            </box>
          </geometry>
          <material>
            <script>
              <uri>file://media/materials/scripts/gazebo.material</uri>
              <name>Gazebo/Wood</name>
            </script>
            <ambient>1 1 1 1</ambient>
          </material>
          <meta>
            <layer>0</layer>
          </meta>
        </visual>
        <collision name='Wall_14_Collision_0'>
          <geometry>
            <box>
              <size>0.171349 0.15 2.5</size>
            </box>
          </geometry>
          <pose frame=''>-1.33225 0 1.25 0 -0 0</pose>
          <max_contacts>10</max_contacts>
          <surface>
            <contact>
              <ode/>
            </contact>
            <bounce/>
            <friction>
              <torsional>
                <ode/>
              </torsional>
              <ode/>
            </friction>
          </surface>
        </collision>
        <visual name='Wall_14_Visual_1'>
          <pose frame=''>0.585675 0 1.25 0 -0 0</pose>
          <geometry>
            <box>
              <size>1.66449 0.15 2.5</size>
            </box>
          </geometry>
          <material>
            <script>
              <uri>file://media/materials/scripts/gazebo.material</uri>
              <name>Gazebo/Wood</name>
            </script>
            <ambient>1 1 1 1</ambient>
          </material>
          <meta>
            <layer>0</layer>
          </meta>
        </visual>
        <collision name='Wall_14_Collision_1'>
          <geometry>
            <box>
              <size>1.66449 0.15 2.5</size>
            </box>
          </geometry>
          <pose frame=''>0.585675 0 1.25 0 -0 0</pose>
          <max_contacts>10</max_contacts>
          <surface>
            <contact>
              <ode/>
            </contact>
            <bounce/>
            <friction>
              <torsional>
                <ode/>
              </torsional>
              <ode/>
            </friction>
          </surface>
        </collision>
        <visual name='Wall_14_Visual_2'>
          <pose frame=''>-0.746572 0 2.25 0 -0 0</pose>
          <geometry>
            <box>
              <size>1 0.15 0.5</size>
            </box>
          </geometry>
          <material>
            <script>
              <uri>file://media/materials/scripts/gazebo.material</uri>
              <name>Gazebo/Wood</name>
            </script>
            <ambient>1 1 1 1</ambient>
          </material>
          <meta>
            <layer>0</layer>
          </meta>
        </visual>
        <collision name='Wall_14_Collision_2'>
          <geometry>
            <box>
              <size>1 0.15 0.5</size>
            </box>
          </geometry>
          <pose frame=''>-0.746572 0 2.25 0 -0 0</pose>
          <max_contacts>10</max_contacts>
          <surface>
            <contact>
              <ode/>
            </contact>
            <bounce/>
            <friction>
              <torsional>
                <ode/>
              </torsional>
              <ode/>
            </friction>
          </surface>
        </collision>
        <self_collide>0</self_collide>
        <kinematic>0</kinematic>
      </link>
      <link name='Wall_16'>
        <collision name='Wall_16_Collision'>
          <geometry>
            <box>
              <size>4.25 0.15 2.5</size>
            </box>
          </geometry>
          <pose frame=''>0 0 1.25 0 -0 0</pose>
          <max_contacts>10</max_contacts>
          <surface>
            <contact>
              <ode/>
            </contact>
            <bounce/>
            <friction>
              <torsional>
                <ode/>
              </torsional>
              <ode/>
            </friction>
          </surface>
        </collision>
        <visual name='Wall_16_Visual'>
          <pose frame=''>0 0 1.25 0 -0 0</pose>
          <geometry>
            <box>
              <size>4.25 0.15 2.5</size>
            </box>
          </geometry>
          <material>
            <script>
              <uri>file://media/materials/scripts/gazebo.material</uri>
              <name>Gazebo/CeilingTiled</name>
            </script>
            <ambient>1 1 1 1</ambient>
          </material>
          <meta>
            <layer>0</layer>
          </meta>
        </visual>
        <pose frame=''>7.05 3.75 0 0 -0 1.5708</pose>
        <self_collide>0</self_collide>
        <kinematic>0</kinematic>
      </link>
      <link name='Wall_17'>
        <collision name='Wall_17_Collision'>
          <geometry>
            <box>
              <size>14.25 0.15 2.5</size>
            </box>
          </geometry>
          <pose frame=''>0 0 1.25 0 -0 0</pose>
          <max_contacts>10</max_contacts>
          <surface>
            <contact>
              <ode/>
            </contact>
            <bounce/>
            <friction>
              <torsional>
                <ode/>
              </torsional>
              <ode/>
            </friction>
          </surface>
        </collision>
        <visual name='Wall_17_Visual'>
          <pose frame=''>0 0 1.25 0 -0 0</pose>
          <geometry>
            <box>
              <size>14.25 0.15 2.5</size>
            </box>
          </geometry>
          <material>
            <script>
              <uri>file://media/materials/scripts/gazebo.material</uri>
              <name>Gazebo/CeilingTiled</name>
            </script>
            <ambient>1 1 1 1</ambient>
          </material>
          <meta>
            <layer>0</layer>
          </meta>
        </visual>
        <pose frame=''>0 5.8 0 0 -0 3.14159</pose>
        <self_collide>0</self_collide>
        <kinematic>0</kinematic>
      </link>
      <link name='Wall_18'>
        <collision name='Wall_18_Collision'>
          <geometry>
            <box>
              <size>11.75 0.15 2.5</size>
            </box>
          </geometry>
          <pose frame=''>0 0 1.25 0 -0 0</pose>
          <max_contacts>10</max_contacts>
          <surface>
            <contact>
              <ode/>
            </contact>
            <bounce/>
            <friction>
              <torsional>
                <ode/>
              </torsional>
              <ode/>
            </friction>
          </surface>
        </collision>
        <visual name='Wall_18_Visual'>
          <pose frame=''>0 0 1.25 0 -0 0</pose>
          <geometry>
            <box>
              <size>11.75 0.15 2.5</size>
            </box>
          </geometry>
          <material>
            <script>
              <uri>file://media/materials/scripts/gazebo.material</uri>
              <name>Gazebo/CeilingTiled</name>
            </script>
            <ambient>1 1 1 1</ambient>
          </material>
          <meta>
            <layer>0</layer>
          </meta>
        </visual>
        <pose frame=''>-7.05 0 0 0 0 -1.5708</pose>
        <self_collide>0</self_collide>
        <kinematic>0</kinematic>
      </link>
      <link name='Wall_19'>
        <collision name='Wall_19_Collision'>
          <geometry>
            <box>
              <size>9.75 0.15 2.5</size>
            </box>
          </geometry>
          <pose frame=''>0 0 1.25 0 -0 0</pose>
          <max_contacts>10</max_contacts>
          <surface>
            <contact>
              <ode/>
            </contact>
            <bounce/>
            <friction>
              <torsional>
                <ode/>
              </torsional>
              <ode/>
            </friction>
          </surface>
        </collision>
        <visual name='Wall_19_Visual'>
          <pose frame=''>0 0 1.25 0 -0 0</pose>
          <geometry>
            <box>
              <size>9.75 0.15 2.5</size>
            </box>
          </geometry>
          <material>
            <script>
              <uri>file://media/materials/scripts/gazebo.material</uri>
              <name>Gazebo/CeilingTiled</name>
            </script>
            <ambient>1 1 1 1</ambient>
          </material>
          <meta>
            <layer>0</layer>
          </meta>
        </visual>
        <pose frame=''>-2.25 -5.8 0 0 -0 0</pose>
        <self_collide>0</self_collide>
        <kinematic>0</kinematic>
      </link>
      <link name='Wall_2'>
        <pose frame=''>2.7 -1.35 0 0 0 -1.5708</pose>
        <visual name='Wall_2_Visual_0'>
          <pose frame=''>-3.02331 0 1.25 0 -0 0</pose>
          <geometry>
            <box>
              <size>0.203389 0.15 2.5</size>
            </box>
          </geometry>
          <material>
            <script>
              <uri>file://media/materials/scripts/gazebo.material</uri>
              <name>Gazebo/Bricks</name>
            </script>
            <ambient>1 1 1 1</ambient>
          </material>
          <meta>
            <layer>0</layer>
          </meta>
        </visual>
        <collision name='Wall_2_Collision_0'>
          <geometry>
            <box>
              <size>0.203389 0.15 2.5</size>
            </box>
          </geometry>
          <pose frame=''>-3.02331 0 1.25 0 -0 0</pose>
          <max_contacts>10</max_contacts>
          <surface>
            <contact>
              <ode/>
            </contact>
            <bounce/>
            <friction>
              <torsional>
                <ode/>
              </torsional>
              <ode/>
            </friction>
          </surface>
        </collision>
        <visual name='Wall_2_Visual_1'>
          <pose frame=''>0.601694 0 1.25 0 -0 0</pose>
          <geometry>
            <box>
              <size>5.04661 0.15 2.5</size>
            </box>
          </geometry>
          <material>
            <script>
              <uri>file://media/materials/scripts/gazebo.material</uri>
              <name>Gazebo/Bricks</name>
            </script>
            <ambient>1 1 1 1</ambient>
          </material>
          <meta>
            <layer>0</layer>
          </meta>
        </visual>
        <collision name='Wall_2_Collision_1'>
          <geometry>
            <box>
              <size>5.04661 0.15 2.5</size>
            </box>
          </geometry>
          <pose frame=''>0.601694 0 1.25 0 -0 0</pose>
          <max_contacts>10</max_contacts>
          <surface>
            <contact>
              <ode/>
            </contact>
            <bounce/>
            <friction>
              <torsional>
                <ode/>
              </torsional>
              <ode/>
            </friction>
          </surface>
        </collision>
        <visual name='Wall_2_Visual_2'>
          <pose frame=''>-2.42161 0 2.25 0 -0 0</pose>
          <geometry>
            <box>
              <size>1 0.15 0.5</size>
            </box>
          </geometry>
          <material>
            <script>
              <uri>file://media/materials/scripts/gazebo.material</uri>
              <name>Gazebo/Bricks</name>
            </script>
            <ambient>1 1 1 1</ambient>
          </material>
          <meta>
            <layer>0</layer>
          </meta>
        </visual>
        <collision name='Wall_2_Collision_2'>
          <geometry>
            <box>
              <size>1 0.15 0.5</size>
            </box>
          </geometry>
          <pose frame=''>-2.42161 0 2.25 0 -0 0</pose>
          <max_contacts>10</max_contacts>
          <surface>
            <contact>
              <ode/>
            </contact>
            <bounce/>
            <friction>
              <torsional>
                <ode/>
              </torsional>
              <ode/>
            </friction>
          </surface>
        </collision>
        <self_collide>0</self_collide>
        <kinematic>0</kinematic>
      </link>
      <link name='Wall_3'>
        <collision name='Wall_3_Collision'>
          <geometry>
            <box>
              <size>8.25 0.15 2.5</size>
            </box>
          </geometry>
          <pose frame=''>0 0 1.25 0 -0 0</pose>
          <max_contacts>10</max_contacts>
          <surface>
            <contact>
              <ode/>
            </contact>
            <bounce/>
            <friction>
              <torsional>
                <ode/>
              </torsional>
              <ode/>
            </friction>
          </surface>
        </collision>
        <visual name='Wall_3_Visual'>
          <pose frame=''>0 0 1.25 0 -0 0</pose>
          <geometry>
            <box>
              <size>8.25 0.15 2.5</size>
            </box>
          </geometry>
          <material>
            <script>
              <uri>file://media/materials/scripts/gazebo.material</uri>
              <name>Gazebo/Bricks</name>
            </script>
            <ambient>1 1 1 1</ambient>
          </material>
          <meta>
            <layer>0</layer>
          </meta>
        </visual>
        <pose frame=''>-1.35 -4.4 0 0 -0 3.14159</pose>
        <self_collide>0</self_collide>
        <kinematic>0</kinematic>
      </link>
      <link name='Wall_4'>
        <collision name='Wall_4_Collision'>
          <geometry>
            <box>
              <size>9 0.15 2.5</size>
            </box>
          </geometry>
          <pose frame=''>0 0 1.25 0 -0 0</pose>
          <max_contacts>10</max_contacts>
          <surface>
            <contact>
              <ode/>
            </contact>
            <bounce/>
            <friction>
              <torsional>
                <ode/>
              </torsional>
              <ode/>
            </friction>
          </surface>
        </collision>
        <visual name='Wall_4_Visual'>
          <pose frame=''>0 0 1.25 0 -0 0</pose>
          <geometry>
            <box>
              <size>9 0.15 2.5</size>
            </box>
          </geometry>
          <material>
            <script>
              <uri>file://media/materials/scripts/gazebo.material</uri>
              <name>Gazebo/Bricks</name>
            </script>
            <ambient>1 1 1 1</ambient>
          </material>
          <meta>
            <layer>0</layer>
          </meta>
        </visual>
        <pose frame=''>-5.4 0.025 0 0 -0 1.5708</pose>
        <self_collide>0</self_collide>
        <kinematic>0</kinematic>
      </link>
      <link name='Wall_5'>
        <collision name='Wall_5_Collision'>
          <geometry>
            <box>
              <size>11 0.15 2.5</size>
            </box>
          </geometry>
          <pose frame=''>0 0 1.25 0 -0 0</pose>
          <max_contacts>10</max_contacts>
          <surface>
            <contact>
              <ode/>
            </contact>
            <bounce/>
            <friction>
              <torsional>
                <ode/>
              </torsional>
              <ode/>
            </friction>
          </surface>
        </collision>
        <visual name='Wall_5_Visual'>
          <pose frame=''>0 0 1.25 0 -0 0</pose>
          <geometry>
            <box>
              <size>11 0.15 2.5</size>
            </box>
          </geometry>
          <material>
            <script>
              <uri>file://media/materials/scripts/gazebo.material</uri>
              <name>Gazebo/Bricks</name>
            </script>
            <ambient>1 1 1 1</ambient>
          </material>
          <meta>
            <layer>0</layer>
          </meta>
        </visual>
        <pose frame=''>0.025 4.45 0 0 -0 0</pose>
        <self_collide>0</self_collide>
        <kinematic>0</kinematic>
      </link>
      <link name='Wall_6'>
        <collision name='Wall_6_Collision'>
          <geometry>
            <box>
              <size>2.75 0.15 2.5</size>
            </box>
          </geometry>
          <pose frame=''>0 0 1.25 0 -0 0</pose>
          <max_contacts>10</max_contacts>
          <surface>
            <contact>
              <ode/>
            </contact>
            <bounce/>
            <friction>
              <torsional>
                <ode/>
              </torsional>
              <ode/>
            </friction>
          </surface>
        </collision>
        <visual name='Wall_6_Visual'>
          <pose frame=''>0 0 1.25 0 -0 0</pose>
          <geometry>
            <box>
              <size>2.75 0.15 2.5</size>
            </box>
          </geometry>
          <material>
            <script>
              <uri>file://media/materials/scripts/gazebo.material</uri>
              <name>Gazebo/Bricks</name>
            </script>
            <ambient>1 1 1 1</ambient>
          </material>
          <meta>
            <layer>0</layer>
          </meta>
        </visual>
        <pose frame=''>5.45 3.15 0 0 0 -1.5708</pose>
        <self_collide>0</self_collide>
        <kinematic>0</kinematic>
      </link>
      <link name='Wall_8'>
        <collision name='Wall_8_Collision'>
          <geometry>
            <box>
              <size>3.25 0.15 2.5</size>
            </box>
          </geometry>
          <pose frame=''>0 0 1.25 0 -0 0</pose>
          <max_contacts>10</max_contacts>
          <surface>
            <contact>
              <ode/>
            </contact>
            <bounce/>
            <friction>
              <torsional>
                <ode/>
              </torsional>
              <ode/>
            </friction>
          </surface>
        </collision>
        <visual name='Wall_8_Visual'>
          <pose frame=''>0 0 1.25 0 -0 0</pose>
          <geometry>
            <box>
              <size>3.25 0.15 2.5</size>
            </box>
          </geometry>
          <material>
            <script>
              <uri>file://media/materials/scripts/gazebo.material</uri>
              <name>Gazebo/Wood</name>
            </script>
            <ambient>1 1 1 1</ambient>
          </material>
          <meta>
            <layer>0</layer>
          </meta>
        </visual>
        <pose frame=''>-1.49883 2.86179 0 0 0 -1.5708</pose>
        <self_collide>0</self_collide>
        <kinematic>0</kinematic>
      </link>
      <link name='Wall_9'>
        <collision name='Wall_9_Collision'>
          <geometry>
            <box>
              <size>1.25 0.15 2.5</size>
            </box>
          </geometry>
          <pose frame=''>0 0 1.25 0 -0 0</pose>
          <max_contacts>10</max_contacts>
          <surface>
            <contact>
              <ode/>
            </contact>
            <bounce/>
            <friction>
              <torsional>
                <ode/>
              </torsional>
              <ode/>
            </friction>
          </surface>
        </collision>
        <visual name='Wall_9_Visual'>
          <pose frame=''>0 0 1.25 0 -0 0</pose>
          <geometry>
            <box>
              <size>1.25 0.15 2.5</size>
            </box>
          </geometry>
          <material>
            <script>
              <uri>file://media/materials/scripts/gazebo.material</uri>
              <name>Gazebo/Wood</name>
            </script>
            <ambient>1 1 1 1</ambient>
          </material>
          <meta>
            <layer>0</layer>
          </meta>
        </visual>
        <pose frame=''>-2.04883 1.31179 0 0 -0 3.14159</pose>
        <self_collide>0</self_collide>
        <kinematic>0</kinematic>
      </link>
      <static>1</static>
    </model>
    <model name='person_standing_clone'>
      <link name='link'>
        <inertial>
          <pose frame=''>0 -0.1 0.95 0 -0 0</pose>
          <mass>80</mass>
          <inertia>
            <ixx>24.88</ixx>
            <ixy>0</ixy>
            <ixz>0</ixz>
            <iyy>25.73</iyy>
            <iyz>0</iyz>
            <izz>2.48</izz>
          </inertia>
        </inertial>
        <collision name='bottom'>
          <pose frame=''>0 -0.1 0.01 0 -0 0</pose>
          <geometry>
            <box>
              <size>0.5 0.35 0.02</size>
            </box>
          </geometry>
          <max_contacts>10</max_contacts>
          <surface>
            <contact>
              <ode/>
            </contact>
            <bounce/>
            <friction>
              <torsional>
                <ode/>
              </torsional>
              <ode/>
            </friction>
          </surface>
        </collision>
        <collision name='person'>
          <pose frame=''>0 0 0.02 0.04 -0 0</pose>
          <geometry>
            <mesh>
              <uri>model://person_standing/meshes/standing.dae</uri>
            </mesh>
          </geometry>
          <max_contacts>10</max_contacts>
          <surface>
            <contact>
              <ode/>
            </contact>
            <bounce/>
            <friction>
              <torsional>
                <ode/>
              </torsional>
              <ode/>
            </friction>
          </surface>
        </collision>
        <visual name='visual'>
          <pose frame=''>0 0 0.02 0.04 -0 0</pose>
          <geometry>
            <mesh>
              <uri>model://person_standing/meshes/standing.dae</uri>
            </mesh>
          </geometry>
        </visual>
        <self_collide>0</self_collide>
        <kinematic>0</kinematic>
      </link>
      <pose frame=''>2.12614 1.96433 0 0 -1e-06 -0.000131</pose>
    </model>
    <model name='person_standing_clone_0'>
      <link name='link'>
        <inertial>
          <pose frame=''>0 -0.1 0.95 0 -0 0</pose>
          <mass>80</mass>
          <inertia>
            <ixx>24.88</ixx>
            <ixy>0</ixy>
            <ixz>0</ixz>
            <iyy>25.73</iyy>
            <iyz>0</iyz>
            <izz>2.48</izz>
          </inertia>
        </inertial>
        <collision name='bottom'>
          <pose frame=''>0 -0.1 0.01 0 -0 0</pose>
          <geometry>
            <box>
              <size>0.5 0.35 0.02</size>
            </box>
          </geometry>
          <max_contacts>10</max_contacts>
          <surface>
            <contact>
              <ode/>
            </contact>
            <bounce/>
            <friction>
              <torsional>
                <ode/>
              </torsional>
              <ode/>
            </friction>
          </surface>
        </collision>
        <collision name='person'>
          <pose frame=''>0 0 0.02 0.04 -0 0</pose>
          <geometry>
            <mesh>
              <uri>model://person_standing/meshes/standing.dae</uri>
            </mesh>
          </geometry>
          <max_contacts>10</max_contacts>
          <surface>
            <contact>
              <ode/>
            </contact>
            <bounce/>
            <friction>
              <torsional>
                <ode/>
              </torsional>
              <ode/>
            </friction>
          </surface>
        </collision>
        <visual name='visual'>
          <pose frame=''>0 0 0.02 0.04 -0 0</pose>
          <geometry>
            <mesh>
              <uri>model://person_standing/meshes/standing.dae</uri>
            </mesh>
          </geometry>
        </visual>
        <self_collide>0</self_collide>
        <kinematic>0</kinematic>
      </link>
      <pose frame=''>2.07307 1.13192 0 0 -1e-06 -0.000131</pose>
    </model>
    <model name='person_walking_clone'>
      <link name='link'>
        <inertial>
          <pose frame=''>0 0 0.95 0 -0 0</pose>
          <mass>80</mass>
          <inertia>
            <ixx>27.82</ixx>
            <ixy>0</ixy>
            <ixz>0</ixz>
            <iyy>24.88</iyy>
            <iyz>0</iyz>
            <izz>4.57</izz>
          </inertia>
        </inertial>
        <collision name='bottom'>
          <pose frame=''>0 0 0.01 0 -0 0</pose>
          <geometry>
            <box>
              <size>0.35 0.75 0.02</size>
            </box>
          </geometry>
          <max_contacts>10</max_contacts>
          <surface>
            <contact>
              <ode/>
            </contact>
            <bounce/>
            <friction>
              <torsional>
                <ode/>
              </torsional>
              <ode/>
            </friction>
          </surface>
        </collision>
        <collision name='person'>
          <pose frame=''>0 0 -0.02 0 -0 0</pose>
          <geometry>
            <mesh>
              <uri>model://person_walking/meshes/walking.dae</uri>
            </mesh>
          </geometry>
          <max_contacts>10</max_contacts>
          <surface>
            <contact>
              <ode/>
            </contact>
            <bounce/>
            <friction>
              <torsional>
                <ode/>
              </torsional>
              <ode/>
            </friction>
          </surface>
        </collision>
        <visual name='visual'>
          <pose frame=''>0 0 -0.02 0 -0 0</pose>
          <geometry>
            <mesh>
              <uri>model://person_walking/meshes/walking.dae</uri>
            </mesh>
          </geometry>
        </visual>
        <self_collide>0</self_collide>
        <kinematic>0</kinematic>
      </link>
      <pose frame=''>1.44294 -6.8898 0 1e-06 -1e-06 0.000288</pose>
    </model>
    <state world_name='default'>
      <sim_time>9457 3000000</sim_time>
      <real_time>8053 827527834</real_time>
      <wall_time>1566676094 871892242</wall_time>
      <iterations>7973957</iterations>
      <model name='adaptada'>
        <pose frame=''>1.18856 -0.2523 0 0 -0 0</pose>
        <scale>1 1 1</scale>
        <link name='Wall_0'>
          <pose frame=''>8.23856 -1.6023 0 0 -0 1.5708</pose>
          <velocity>0 0 0 0 -0 0</velocity>
          <acceleration>0 0 0 0 -0 0</acceleration>
          <wrench>0 0 0 0 -0 0</wrench>
        </link>
        <link name='Wall_1'>
          <pose frame=''>6.06356 1.4477 0 0 -0 3.14159</pose>
          <velocity>0 0 0 0 -0 0</velocity>
          <acceleration>0 0 0 0 -0 0</acceleration>
          <wrench>0 0 0 0 -0 0</wrench>
        </link>
        <link name='Wall_11'>
          <pose frame=''>-2.90277 -1.17954 0 0 -0 0</pose>
          <velocity>0 0 0 0 -0 0</velocity>
          <acceleration>0 0 0 0 -0 0</acceleration>
          <wrench>0 0 0 0 -0 0</wrench>
        </link>
        <link name='Wall_12'>
          <pose frame=''>-1.60277 -2.85454 0 0 0 -1.5708</pose>
          <velocity>0 0 0 0 -0 0</velocity>
          <acceleration>0 0 0 0 -0 0</acceleration>
          <wrench>0 0 0 0 -0 0</wrench>
        </link>
        <link name='Wall_14'>
          <pose frame=''>3.8669 2.79045 0 0 0 -1.55466</pose>
          <velocity>0 0 0 0 -0 0</velocity>
          <acceleration>0 0 0 0 -0 0</acceleration>
          <wrench>0 0 0 0 -0 0</wrench>
        </link>
        <link name='Wall_16'>
          <pose frame=''>8.23856 3.4977 0 0 -0 1.5708</pose>
          <velocity>0 0 0 0 -0 0</velocity>
          <acceleration>0 0 0 0 -0 0</acceleration>
          <wrench>0 0 0 0 -0 0</wrench>
        </link>
        <link name='Wall_17'>
          <pose frame=''>1.18856 5.5477 0 0 -0 3.14159</pose>
          <velocity>0 0 0 0 -0 0</velocity>
          <acceleration>0 0 0 0 -0 0</acceleration>
          <wrench>0 0 0 0 -0 0</wrench>
        </link>
        <link name='Wall_18'>
          <pose frame=''>-5.86144 -0.252302 0 0 0 -1.5708</pose>
          <velocity>0 0 0 0 -0 0</velocity>
          <acceleration>0 0 0 0 -0 0</acceleration>
          <wrench>0 0 0 0 -0 0</wrench>
        </link>
        <link name='Wall_19'>
          <pose frame=''>-1.06144 -6.0523 0 0 -0 0</pose>
          <velocity>0 0 0 0 -0 0</velocity>
          <acceleration>0 0 0 0 -0 0</acceleration>
          <wrench>0 0 0 0 -0 0</wrench>
        </link>
        <link name='Wall_2'>
          <pose frame=''>3.88856 -1.6023 0 0 0 -1.5708</pose>
          <velocity>0 0 0 0 -0 0</velocity>
          <acceleration>0 0 0 0 -0 0</acceleration>
          <wrench>0 0 0 0 -0 0</wrench>
        </link>
        <link name='Wall_3'>
          <pose frame=''>-0.16144 -4.6523 0 0 -0 3.14159</pose>
          <velocity>0 0 0 0 -0 0</velocity>
          <acceleration>0 0 0 0 -0 0</acceleration>
          <wrench>0 0 0 0 -0 0</wrench>
        </link>
        <link name='Wall_4'>
          <pose frame=''>-4.21144 -0.227302 0 0 -0 1.5708</pose>
          <velocity>0 0 0 0 -0 0</velocity>
          <acceleration>0 0 0 0 -0 0</acceleration>
          <wrench>0 0 0 0 -0 0</wrench>
        </link>
        <link name='Wall_5'>
          <pose frame=''>1.21356 4.1977 0 0 -0 0</pose>
          <velocity>0 0 0 0 -0 0</velocity>
          <acceleration>0 0 0 0 -0 0</acceleration>
          <wrench>0 0 0 0 -0 0</wrench>
        </link>
        <link name='Wall_6'>
          <pose frame=''>6.63856 2.8977 0 0 0 -1.5708</pose>
          <velocity>0 0 0 0 -0 0</velocity>
          <acceleration>0 0 0 0 -0 0</acceleration>
          <wrench>0 0 0 0 -0 0</wrench>
        </link>
        <link name='Wall_8'>
          <pose frame=''>-0.31027 2.60949 0 0 0 -1.5708</pose>
          <velocity>0 0 0 0 -0 0</velocity>
          <acceleration>0 0 0 0 -0 0</acceleration>
          <wrench>0 0 0 0 -0 0</wrench>
        </link>
        <link name='Wall_9'>
          <pose frame=''>-0.86027 1.05949 0 0 -0 3.14159</pose>
          <velocity>0 0 0 0 -0 0</velocity>
          <acceleration>0 0 0 0 -0 0</acceleration>
          <wrench>0 0 0 0 -0 0</wrench>
        </link>
      </model>
      <model name='ground_plane'>
        <pose frame=''>0 0 0 0 -0 0</pose>
        <scale>1 1 1</scale>
        <link name='link'>
          <pose frame=''>0 0 0 0 -0 0</pose>
          <velocity>0 0 0 0 -0 0</velocity>
          <acceleration>0 0 0 0 -0 0</acceleration>
          <wrench>0 0 0 0 -0 0</wrench>
        </link>
      </model>
      <model name='person_standing_clone'>
        <pose frame=''>2.50776 1.7154 0 -0 -1e-06 -0.202632</pose>
        <scale>1 1 1</scale>
        <link name='link'>
          <pose frame=''>2.50776 1.7154 0 -0 -1e-06 -0.202632</pose>
          <velocity>0 0 0 0 -0 0</velocity>
          <acceleration>1.84319 -1.9409 1.48539 -1.05568 1.25123 3.08503</acceleration>
          <wrench>147.455 -155.272 118.831 0 -0 0</wrench>
        </link>
      </model>
      <model name='person_standing_clone_0'>
        <pose frame=''>2.30835 0.928811 -0 1e-06 1e-06 2.92302</pose>
        <scale>1 1 1</scale>
        <link name='link'>
          <pose frame=''>2.30835 0.928811 -0 1e-06 1e-06 2.92302</pose>
          <velocity>0 0 0 0 -0 0</velocity>
          <acceleration>-1.38746 1.51779 -1.19626 -1.56416 -1.39766 0.018773</acceleration>
          <wrench>-110.997 121.423 -95.7007 0 -0 0</wrench>
        </link>
      </model>
      <model name='person_walking_clone'>
        <pose frame=''>0.908724 -6.46861 0 1e-06 -1e-06 -1.5679</pose>
        <scale>1 1 1</scale>
        <link name='link'>
          <pose frame=''>0.908724 -6.46861 0 1e-06 -1e-06 -1.5679</pose>
          <velocity>0 0 0 0 -0 0</velocity>
          <acceleration>3.59615 -1.64951 2.70837 -0.951894 -0.152968 3.03625</acceleration>
          <wrench>287.692 -131.961 216.67 0 -0 0</wrench>
        </link>
      </model>
      <model name='person_walking_clone_clone'>
        <pose frame=''>2.60306 -7.48962 0 -1e-06 -1e-06 -1.56465</pose>
        <scale>1 1 1</scale>
        <link name='link'>
          <pose frame=''>2.60306 -7.48962 0 -1e-06 -1e-06 -1.56465</pose>
          <velocity>0 0 0 0 -0 0</velocity>
          <acceleration>-2.05898 0.960505 -2.65128 1.98061 -1.2568 -3.04287</acceleration>
          <wrench>-164.718 76.8404 -212.102 0 -0 0</wrench>
        </link>
      </model>
      <model name='pine_tree'>
        <pose frame=''>-0.464776 -9.44157 0 0 -0 0</pose>
        <scale>1 1 1</scale>
        <link name='link'>
          <pose frame=''>-0.464776 -9.44157 0 0 -0 0</pose>
          <velocity>0 0 0 0 -0 0</velocity>
          <acceleration>0 0 0 0 -0 0</acceleration>
          <wrench>0 0 0 0 -0 0</wrench>
        </link>
      </model>
      <model name='pine_tree_clone'>
        <pose frame=''>2.02707 -9.49993 0 0 -0 0</pose>
        <scale>1 1 1</scale>
        <link name='link'>
          <pose frame=''>2.02707 -9.49993 0 0 -0 0</pose>
          <velocity>0 0 0 0 -0 0</velocity>
          <acceleration>0 0 0 0 -0 0</acceleration>
          <wrench>0 0 0 0 -0 0</wrench>
        </link>
      </model>
      <model name='pine_tree_clone_0'>
        <pose frame=''>4.45448 -9.44379 0 0 -0 0</pose>
        <scale>1 1 1</scale>
        <link name='link'>
          <pose frame=''>4.45448 -9.44379 0 0 -0 0</pose>
          <velocity>0 0 0 0 -0 0</velocity>
          <acceleration>0 0 0 0 -0 0</acceleration>
          <wrench>0 0 0 0 -0 0</wrench>
        </link>
      </model>
      <model name='prius_hybrid'>
        <pose frame=''>5.99272 -1.92671 0.011641 -2e-06 -0 0.002544</pose>
        <scale>1 1 1</scale>
        <link name='chassis'>
          <pose frame=''>5.99272 -1.92671 0.011641 -2e-06 -0 0.002544</pose>
          <velocity>1e-06 -1e-06 2.1e-05 -3e-06 0 0</velocity>
          <acceleration>0 -0 0 0 -0 0</acceleration>
          <wrench>0 -0 0 0 -0 0</wrench>
        </link>
        <link name='front_left_wheel'>
          <pose frame=''>6.75631 -3.33477 0.311646 -0.033566 0.066818 0.873366</pose>
          <velocity>0 -0 3.2e-05 1e-06 1e-06 0</velocity>
          <acceleration>0 -0 -0 0 -0 0</acceleration>
          <wrench>0 -0 -0 0 -0 0</wrench>
        </link>
        <link name='front_right_wheel'>
          <pose frame=''>5.23631 -3.33864 0.311646 -0.023109 0.063526 0.816581</pose>
          <velocity>0 0 3.1e-05 0 1e-06 7e-06</velocity>
          <acceleration>0 -0 0 0 -0 0</acceleration>
          <wrench>0 -0 0 0 -0 0</wrench>
        </link>
        <link name='rear_axle'>
          <pose frame=''>5.98903 -0.476716 0.311637 -2e-06 -4e-06 0.002544</pose>
          <velocity>1e-06 -0 1.5e-05 -4e-06 -4e-06 -0</velocity>
          <acceleration>-0 -0 0 -0.002953 -7e-06 0</acceleration>
          <wrench>-0 -0 0 0 -0 0</wrench>
        </link>
        <link name='rear_left_wheel'>
          <pose frame=''>6.77503 -0.474716 0.311647 -0.064337 -4e-06 0.002544</pose>
          <velocity>1e-06 -0 2.5e-05 2e-06 -1e-06 -0</velocity>
          <acceleration>-0 -0 -0 0 -0 0</acceleration>
          <wrench>-0 -0 -0 0 -0 0</wrench>
        </link>
        <link name='rear_right_wheel'>
          <pose frame=''>5.20303 -0.478715 0.311647 -0.053814 8e-06 0.002544</pose>
          <velocity>2e-06 0 2.5e-05 -1e-06 2e-06 -0</velocity>
          <acceleration>0 -0 -0 0 -0 0</acceleration>
          <wrench>0 -0 -0 0 -0 0</wrench>
        </link>
        <link name='steering_wheel'>
          <pose frame=''>6.35005 -2.55314 0.997957 -8.1e-05 1.30202 1.57334</pose>
          <velocity>1e-06 2e-06 2.3e-05 -3e-06 -0 -0</velocity>
          <acceleration>0 -0 0 0 -0 0</acceleration>
          <wrench>0 -0 0 0 -0 0</wrench>
        </link>
      </model>
      <model name='robot_description'>
        <pose frame=''>-2.46332 -7.12859 -0.012485 -2e-06 0.016619 -0.036053</pose>
        <scale>1 1 1</scale>
        <link name='base_footprint'>
          <pose frame=''>-2.46332 -7.12859 -0.012485 -2e-06 0.016619 -0.036053</pose>
          <velocity>-0.000375 1.3e-05 -0.001052 8.3e-05 0.00171 -4.5e-05</velocity>
          <acceleration>-0 -0 0 0 -0 0</acceleration>
          <wrench>-0 -0 0 0 -0 0</wrench>
        </link>
        <link name='left_caster_hub_link'>
          <pose frame=''>-3.03435 -6.91786 0.097146 1.4e-05 -0.016612 3.10442</pose>
          <velocity>-0.000509 1.2e-05 0.000162 0.000256 0.00264 -2e-06</velocity>
          <acceleration>0 0 -0 0 -0 0</acceleration>
          <wrench>0 0 -0 0 -0 0</wrench>
        </link>
        <link name='left_caster_wheel_link'>
          <pose frame=''>-2.9744 -6.92009 0.096148 1.2e-05 -0.345371 3.10442</pose>
          <velocity>-0.00055 5e-06 -6e-06 -4.7e-05 -0.005499 4.2e-05</velocity>
          <acceleration>0 0 0 0 -0 0</acceleration>
          <wrench>0 0 0 0 -0 0</wrench>
        </link>
        <link name='left_front_wheel_link'>
          <pose frame=''>-2.45077 -6.85886 0.15749 -6e-06 0.956266 -0.036056</pose>
          <velocity>-3.1e-05 -1.1e-05 -0.001042 6.7e-05 -0.000179 -7.6e-05</velocity>
          <acceleration>-0 -0 0 0 -0 0</acceleration>
          <wrench>-0 -0 0 0 -0 0</wrench>
        </link>
        <link name='right_caster_hub_link'>
          <pose frame=''>-3.04805 -7.29762 0.097147 -2.6e-05 0.016612 -0.036956</pose>
          <velocity>-0.000509 1.7e-05 0.000163 -7e-05 0.002642 0.000158</velocity>
          <acceleration>0 0 0 0 -0 0</acceleration>
          <wrench>0 0 0 0 -0 0</wrench>
        </link>
        <link name='right_caster_wheel_link'>
          <pose frame=''>-2.9881 -7.29984 0.096149 -3.14156 0.31094 3.10464</pose>
          <velocity>-0.000549 3.7e-05 -4e-06 -0.000371 -0.005489 9.7e-05</velocity>
          <acceleration>-0 0 0 -0 -0 -0</acceleration>
          <wrench>-0 0 0 0 -0 0</wrench>
        </link>
        <link name='right_front_wheel_link'>
          <pose frame=''>-2.47023 -7.39851 0.157492 -2e-05 -1.42292 -0.036032</pose>
          <velocity>-2.8e-05 1.3e-05 -0.00104 -7.6e-05 -0.000171 0.000113</velocity>
          <acceleration>0 0 -0 0 -0 0</acceleration>
          <wrench>0 0 -0 0 -0 0</wrench>
        </link>
      </model>
      <model name='table_marble'>
        <pose frame=''>1.21684 -2.26586 0.648 0 -0 0</pose>
        <scale>1 1 1</scale>
        <link name='link'>
          <pose frame=''>1.21684 -2.26586 0.648 0 -0 0</pose>
          <velocity>0 0 0 0 -0 0</velocity>
          <acceleration>0 0 0 0 -0 0</acceleration>
          <wrench>0 0 0 0 -0 0</wrench>
        </link>
      </model>
      <model name='unit_cylinder'>
        <pose frame=''>-2.46034 2.54385 0.649995 0 -0 0</pose>
        <scale>1 1 1</scale>
        <link name='link'>
          <pose frame=''>-2.46034 2.54385 0.649995 0 -0 0</pose>
          <velocity>0 0 0 0 -0 0</velocity>
          <acceleration>0 0 -9.8 0 -0 0</acceleration>
          <wrench>0 0 -9.8 0 -0 0</wrench>
        </link>
      </model>
      <light name='sun'>
        <pose frame=''>0 0 10 0 -0 0</pose>
      </light>
    </state>
    <model name='prius_hybrid'>
      <pose frame=''>6.13883 -3.17797 0.03 0 -0 0</pose>
      <link name='chassis'>
        <inertial>
          <mass>1326</mass>
          <pose frame=''>0 -0.266 0.48 0 -0 0</pose>
          <inertia>
            <ixx>2581.13</ixx>
            <ixy>0</ixy>
            <iyy>591.308</iyy>
            <ixz>0</ixz>
            <iyz>0</iyz>
            <izz>2681.95</izz>
          </inertia>
        </inertial>
        <visual name='chassis_visual'>
          <geometry>
            <mesh>
              <uri>model://prius_hybrid/meshes/Hybrid.obj</uri>
              <scale>0.01 0.01 0.01</scale>
              <submesh>
                <name>Hybrid</name>
                <center>0</center>
              </submesh>
            </mesh>
          </geometry>
        </visual>
        <visual name='interior_visual'>
          <geometry>
            <mesh>
              <uri>model://prius_hybrid/meshes/Hybrid.obj</uri>
              <scale>0.01 0.01 0.01</scale>
              <submesh>
                <name>Hybrid_Interior</name>
                <center>0</center>
              </submesh>
            </mesh>
          </geometry>
        </visual>
        <visual name='windows_visual'>
          <geometry>
            <mesh>
              <uri>model://prius_hybrid/meshes/Hybrid.obj</uri>
              <scale>0.01 0.01 0.01</scale>
              <submesh>
                <name>Hybrid_Windows</name>
                <center>0</center>
              </submesh>
            </mesh>
          </geometry>
        </visual>
        <collision name='chassis'>
          <pose frame=''>0 0.05 0.625 0 -0 0</pose>
          <geometry>
            <box>
              <size>1.7526 2.1 0.95</size>
            </box>
          </geometry>
          <max_contacts>10</max_contacts>
          <surface>
            <contact>
              <ode/>
            </contact>
            <bounce/>
            <friction>
              <torsional>
                <ode/>
              </torsional>
              <ode/>
            </friction>
          </surface>
        </collision>
        <collision name='front_bumper'>
          <pose frame=''>0 -2 0.458488 0 -0 0</pose>
          <geometry>
            <box>
              <size>1.33728 0.48 0.566691</size>
            </box>
          </geometry>
          <max_contacts>10</max_contacts>
          <surface>
            <contact>
              <ode/>
            </contact>
            <bounce/>
            <friction>
              <torsional>
                <ode/>
              </torsional>
              <ode/>
            </friction>
          </surface>
        </collision>
        <collision name='hood'>
          <pose frame=''>0 -1.90084 0.676305 0.341247 -0 0</pose>
          <geometry>
            <box>
              <size>1.59797 0.493107 0.265468</size>
            </box>
          </geometry>
          <max_contacts>10</max_contacts>
          <surface>
            <contact>
              <ode/>
            </contact>
            <bounce/>
            <friction>
              <torsional>
                <ode/>
              </torsional>
              <ode/>
            </friction>
          </surface>
        </collision>
        <collision name='windshield'>
          <pose frame=''>0 -0.875105 1.03227 0.335476 -0 0</pose>
          <geometry>
            <box>
              <size>1.16838 1.65425 0.272347</size>
            </box>
          </geometry>
          <max_contacts>10</max_contacts>
          <surface>
            <contact>
              <ode/>
            </contact>
            <bounce/>
            <friction>
              <torsional>
                <ode/>
              </torsional>
              <ode/>
            </friction>
          </surface>
        </collision>
        <collision name='top_front'>
          <pose frame=''>0 0.161236 1.38604 0.13503 -0 0</pose>
          <geometry>
            <box>
              <size>1.27915 0.625988 0.171868</size>
            </box>
          </geometry>
          <max_contacts>10</max_contacts>
          <surface>
            <contact>
              <ode/>
            </contact>
            <bounce/>
            <friction>
              <torsional>
                <ode/>
              </torsional>
              <ode/>
            </friction>
          </surface>
        </collision>
        <collision name='top_rear'>
          <pose frame=''>0 0.817696 1.36007 -0.068997 0 0</pose>
          <geometry>
            <box>
              <size>1.28513 0.771189 0.226557</size>
            </box>
          </geometry>
          <max_contacts>10</max_contacts>
          <surface>
            <contact>
              <ode/>
            </contact>
            <bounce/>
            <friction>
              <torsional>
                <ode/>
              </torsional>
              <ode/>
            </friction>
          </surface>
        </collision>
        <collision name='rear_window'>
          <pose frame=''>0 1.64053 1.17513 -0.262017 0 0</pose>
          <geometry>
            <box>
              <size>1.26785 1.11634 0.244286</size>
            </box>
          </geometry>
          <max_contacts>10</max_contacts>
          <surface>
            <contact>
              <ode/>
            </contact>
            <bounce/>
            <friction>
              <torsional>
                <ode/>
              </torsional>
              <ode/>
            </friction>
          </surface>
        </collision>
        <collision name='trunk'>
          <pose frame=''>0 1.63706 0.88818 0 -0 0</pose>
          <geometry>
            <box>
              <size>1.78806 1.13899 0.482746</size>
            </box>
          </geometry>
          <max_contacts>10</max_contacts>
          <surface>
            <contact>
              <ode/>
            </contact>
            <bounce/>
            <friction>
              <torsional>
                <ode/>
              </torsional>
              <ode/>
            </friction>
          </surface>
        </collision>
        <collision name='back_bumper'>
          <pose frame=''>0 2.05445 0.57787 0 -0 0</pose>
          <geometry>
            <box>
              <size>1.78165 0.512093 0.581427</size>
            </box>
          </geometry>
          <max_contacts>10</max_contacts>
          <surface>
            <contact>
              <ode/>
            </contact>
            <bounce/>
            <friction>
              <torsional>
                <ode/>
              </torsional>
              <ode/>
            </friction>
          </surface>
        </collision>
        <self_collide>0</self_collide>
        <kinematic>0</kinematic>
      </link>
      <link name='steering_wheel'>
        <pose frame=''>0.357734 -0.627868 0.988243 -1.3021 0 0</pose>
        <inertial>
          <mass>1</mass>
          <inertia>
            <ixx>0.145833</ixx>
            <ixy>0</ixy>
            <ixz>0</ixz>
            <iyy>0.145833</iyy>
            <iyz>0</iyz>
            <izz>0.125</izz>
          </inertia>
        </inertial>
        <collision name='collision'>
          <geometry>
            <cylinder>
              <radius>0.178172</radius>
              <length>0.041845</length>
            </cylinder>
          </geometry>
          <surface>
            <contact>
              <ode>
                <min_depth>0.003</min_depth>
              </ode>
            </contact>
            <bounce/>
            <friction>
              <torsional>
                <ode/>
              </torsional>
              <ode/>
            </friction>
          </surface>
          <max_contacts>10</max_contacts>
        </collision>
        <visual name='visual'>
          <pose frame=''>0 0 0 1.3021 -0 0</pose>
          <geometry>
            <mesh>
              <uri>model://prius_hybrid/meshes/Hybrid.obj</uri>
              <scale>0.01 0.01 0.01</scale>
              <submesh>
                <name>Steering_Wheel</name>
                <center>1</center>
              </submesh>
            </mesh>
          </geometry>
        </visual>
        <self_collide>0</self_collide>
        <kinematic>0</kinematic>
      </link>
      <link name='front_left_wheel'>
        <pose frame=''>0.76 -1.41 0.3 0 -0 0</pose>
        <inertial>
          <mass>11</mass>
          <inertia>
            <ixx>0.586312</ixx>
            <ixy>0</ixy>
            <iyy>0.335529</iyy>
            <ixz>0</ixz>
            <iyz>0</iyz>
            <izz>0.335529</izz>
          </inertia>
        </inertial>
        <visual name='visual'>
          <pose frame=''>0.04 0 0 0 -0 0</pose>
          <geometry>
            <mesh>
              <uri>model://prius_hybrid/meshes/Hybrid.obj</uri>
              <scale>0.01 0.01 0.01</scale>
              <submesh>
                <name>Wheel_Front_Left_</name>
                <center>1</center>
              </submesh>
            </mesh>
          </geometry>
        </visual>
        <collision name='collision'>
          <pose frame=''>0 0 0 3.14159 1.57079 3.14159</pose>
          <geometry>
            <sphere>
              <radius>0.31265</radius>
            </sphere>
          </geometry>
          <surface>
            <friction>
              <ode>
                <mu>0.9</mu>
                <mu2>0.9</mu2>
                <slip1>0</slip1>
                <slip2>0</slip2>
              </ode>
              <torsional>
                <ode/>
              </torsional>
            </friction>
            <contact>
              <ode>
                <min_depth>0.001</min_depth>
                <kp>1e+09</kp>
              </ode>
            </contact>
            <bounce/>
          </surface>
          <max_contacts>10</max_contacts>
        </collision>
        <self_collide>0</self_collide>
        <kinematic>0</kinematic>
      </link>
      <link name='front_right_wheel'>
        <pose frame=''>-0.76 -1.41 0.3 0 -0 0</pose>
        <inertial>
          <mass>11</mass>
          <inertia>
            <ixx>0.586312</ixx>
            <ixy>0</ixy>
            <iyy>0.335529</iyy>
            <ixz>0</ixz>
            <iyz>0</iyz>
            <izz>0.335529</izz>
          </inertia>
        </inertial>
        <visual name='visual'>
          <pose frame=''>-0.04 0 0 0 -0 0</pose>
          <pose frame=''>0 0 0 0 -0 0</pose>
          <geometry>
            <mesh>
              <uri>model://prius_hybrid/meshes/Hybrid.obj</uri>
              <scale>0.01 0.01 0.01</scale>
              <submesh>
                <name>Wheel_Front_Right</name>
                <center>1</center>
              </submesh>
            </mesh>
          </geometry>
        </visual>
        <collision name='collision'>
          <pose frame=''>0 0 0 3.14159 1.57079 3.14159</pose>
          <geometry>
            <sphere>
              <radius>0.31265</radius>
            </sphere>
          </geometry>
          <surface>
            <friction>
              <ode>
                <mu>0.9</mu>
                <mu2>0.9</mu2>
                <slip1>0</slip1>
                <slip2>0</slip2>
              </ode>
              <torsional>
                <ode/>
              </torsional>
            </friction>
            <contact>
              <ode>
                <min_depth>0.001</min_depth>
                <kp>1e+09</kp>
              </ode>
            </contact>
            <bounce/>
          </surface>
          <max_contacts>10</max_contacts>
        </collision>
        <self_collide>0</self_collide>
        <kinematic>0</kinematic>
      </link>
      <link name='rear_left_wheel'>
        <pose frame=''>0.786 1.45 0.3 0 -0 0</pose>
        <inertial>
          <mass>11</mass>
          <inertia>
            <ixx>0.586312</ixx>
            <ixy>0</ixy>
            <iyy>0.335529</iyy>
            <ixz>0</ixz>
            <iyz>0</iyz>
            <izz>0.335529</izz>
          </inertia>
        </inertial>
        <visual name='visual'>
          <pose frame=''>0.04 0 0 0 -0 0</pose>
          <geometry>
            <mesh>
              <uri>model://prius_hybrid/meshes/Hybrid.obj</uri>
              <scale>0.01 0.01 0.01</scale>
              <submesh>
                <name>Wheel_Front_Left_</name>
                <center>1</center>
              </submesh>
            </mesh>
          </geometry>
        </visual>
        <collision name='collision'>
          <pose frame=''>0 0 0 3.14159 1.57079 3.14159</pose>
          <geometry>
            <sphere>
              <radius>0.31265</radius>
            </sphere>
          </geometry>
          <surface>
            <friction>
              <ode>
                <mu>1.1</mu>
                <mu2>1.1</mu2>
                <slip1>0</slip1>
                <slip2>0</slip2>
              </ode>
              <torsional>
                <ode/>
              </torsional>
            </friction>
            <contact>
              <ode>
                <min_depth>0.001</min_depth>
                <kp>1e+09</kp>
              </ode>
            </contact>
            <bounce/>
          </surface>
          <max_contacts>10</max_contacts>
        </collision>
        <self_collide>0</self_collide>
        <kinematic>0</kinematic>
      </link>
      <link name='rear_right_wheel'>
        <pose frame=''>-0.786 1.45 0.3 0 -0 0</pose>
        <inertial>
          <mass>11</mass>
          <inertia>
            <ixx>0.586312</ixx>
            <ixy>0</ixy>
            <iyy>0.335529</iyy>
            <ixz>0</ixz>
            <iyz>0</iyz>
            <izz>0.335529</izz>
          </inertia>
        </inertial>
        <visual name='visual'>
          <pose frame=''>-0.04 0 0 0 -0 0</pose>
          <geometry>
            <mesh>
              <uri>model://prius_hybrid/meshes/Hybrid.obj</uri>
              <scale>0.01 0.01 0.01</scale>
              <submesh>
                <name>Wheel_Front_Right</name>
                <center>1</center>
              </submesh>
            </mesh>
          </geometry>
        </visual>
        <collision name='collision'>
          <pose frame=''>0 0 0 3.14159 1.57079 3.14159</pose>
          <geometry>
            <sphere>
              <radius>0.31265</radius>
            </sphere>
          </geometry>
          <surface>
            <friction>
              <ode>
                <mu>1.1</mu>
                <mu2>1.1</mu2>
                <slip1>0</slip1>
                <slip2>0</slip2>
              </ode>
              <torsional>
                <ode/>
              </torsional>
            </friction>
            <contact>
              <ode>
                <min_depth>0.001</min_depth>
                <kp>1e+09</kp>
              </ode>
            </contact>
            <bounce/>
          </surface>
          <max_contacts>10</max_contacts>
        </collision>
        <self_collide>0</self_collide>
        <kinematic>0</kinematic>
      </link>
      <joint name='front_left_combined_joint' type='universal'>
        <pose frame=''>0 0 0 -0.087266 0 0</pose>
        <child>front_left_wheel</child>
        <parent>chassis</parent>
        <axis>
          <xyz>0 0 1</xyz>
          <limit>
            <lower>-0.8727</lower>
            <upper>0.8727</upper>
          </limit>
          <use_parent_model_frame>0</use_parent_model_frame>
          <dynamics>
            <spring_reference>0</spring_reference>
            <spring_stiffness>0</spring_stiffness>
          </dynamics>
        </axis>
        <axis2>
          <xyz>1 0 0</xyz>
          <dynamics>
            <friction>18.0474</friction>
            <spring_reference>0</spring_reference>
            <spring_stiffness>0</spring_stiffness>
          </dynamics>
          <use_parent_model_frame>0</use_parent_model_frame>
        </axis2>
      </joint>
      <joint name='front_right_combined_joint' type='universal'>
        <pose frame=''>0 0 0 -0.087266 0 0</pose>
        <child>front_right_wheel</child>
        <parent>chassis</parent>
        <axis>
          <xyz>0 0 1</xyz>
          <limit>
            <lower>-0.8727</lower>
            <upper>0.8727</upper>
          </limit>
          <use_parent_model_frame>0</use_parent_model_frame>
          <dynamics>
            <spring_reference>0</spring_reference>
            <spring_stiffness>0</spring_stiffness>
          </dynamics>
        </axis>
        <axis2>
          <xyz>1 0 0</xyz>
          <dynamics>
            <friction>18.0474</friction>
            <spring_reference>0</spring_reference>
            <spring_stiffness>0</spring_stiffness>
          </dynamics>
          <use_parent_model_frame>0</use_parent_model_frame>
        </axis2>
      </joint>
      <link name='rear_axle'>
        <pose frame=''>0 1.45 0.3 0 -0 0</pose>
        <inertial>
          <mass>30</mass>
          <inertia>
            <ixx>0.084375</ixx>
            <ixy>0</ixy>
            <iyy>4.64581</iyy>
            <ixz>0</ixz>
            <iyz>0</iyz>
            <izz>4.64581</izz>
          </inertia>
        </inertial>
        <visual name='visual'>
          <pose frame=''>0 0 0 3.14159 1.57079 3.14159</pose>
          <geometry>
            <cylinder>
              <length>1.357</length>
              <radius>0.075</radius>
            </cylinder>
          </geometry>
          <material>
            <script>
              <name>Gazebo/Grey</name>
              <uri>file://media/materials/scripts/gazebo.material</uri>
            </script>
          </material>
        </visual>
        <self_collide>0</self_collide>
        <kinematic>0</kinematic>
      </link>
      <joint name='rear_axle_joint' type='revolute'>
        <child>rear_axle</child>
        <parent>chassis</parent>
        <axis>
          <xyz>0 1 0</xyz>
          <limit>
            <lower>-0.0508906</lower>
            <upper>0.0508906</upper>
          </limit>
          <dynamics>
            <spring_stiffness>20000</spring_stiffness>
            <damping>2000</damping>
            <spring_reference>0</spring_reference>
          </dynamics>
          <use_parent_model_frame>0</use_parent_model_frame>
        </axis>
      </joint>
      <joint name='rear_left_wheel_joint' type='revolute'>
        <child>rear_left_wheel</child>
        <parent>rear_axle</parent>
        <axis>
          <xyz>1 0 0</xyz>
          <dynamics>
            <friction>12.0316</friction>
            <spring_reference>0</spring_reference>
            <spring_stiffness>0</spring_stiffness>
          </dynamics>
          <use_parent_model_frame>0</use_parent_model_frame>
          <limit>
            <lower>-1e+16</lower>
            <upper>1e+16</upper>
          </limit>
        </axis>
      </joint>
      <joint name='rear_right_wheel_joint' type='revolute'>
        <child>rear_right_wheel</child>
        <parent>rear_axle</parent>
        <axis>
          <xyz>1 0 0</xyz>
          <dynamics>
            <friction>12.0316</friction>
            <spring_reference>0</spring_reference>
            <spring_stiffness>0</spring_stiffness>
          </dynamics>
          <use_parent_model_frame>0</use_parent_model_frame>
          <limit>
            <lower>-1e+16</lower>
            <upper>1e+16</upper>
          </limit>
        </axis>
      </joint>
      <joint name='steering_joint' type='revolute'>
        <pose frame=''>-0.002 0 0 0 -0 0</pose>
        <parent>chassis</parent>
        <child>steering_wheel</child>
        <axis>
          <xyz>0 0.964095 0.265556</xyz>
          <limit>
            <lower>-7.85</lower>
            <upper>7.85</upper>
          </limit>
          <dynamics>
            <damping>1</damping>
            <spring_reference>0</spring_reference>
            <spring_stiffness>0</spring_stiffness>
          </dynamics>
          <use_parent_model_frame>1</use_parent_model_frame>
        </axis>
        <physics>
          <ode>
            <cfm_damping>1</cfm_damping>
            <limit>
              <cfm>0</cfm>
              <erp>0.2</erp>
            </limit>
          </ode>
        </physics>
      </joint>
    </model>
    <model name='pine_tree'>
      <static>1</static>
      <link name='link'>
        <collision name='collision'>
          <geometry>
            <mesh>
              <uri>model://pine_tree/meshes/pine_tree.dae</uri>
            </mesh>
          </geometry>
          <max_contacts>10</max_contacts>
          <surface>
            <contact>
              <ode/>
            </contact>
            <bounce/>
            <friction>
              <torsional>
                <ode/>
              </torsional>
              <ode/>
            </friction>
          </surface>
        </collision>
        <visual name='branch'>
          <geometry>
            <mesh>
              <uri>model://pine_tree/meshes/pine_tree.dae</uri>
              <submesh>
                <name>Branch</name>
              </submesh>
            </mesh>
          </geometry>
          <material>
            <script>
              <uri>model://pine_tree/materials/scripts/</uri>
              <uri>model://pine_tree/materials/textures/</uri>
              <name>PineTree/Branch</name>
            </script>
          </material>
        </visual>
        <visual name='bark'>
          <geometry>
            <mesh>
              <uri>model://pine_tree/meshes/pine_tree.dae</uri>
              <submesh>
                <name>Bark</name>
              </submesh>
            </mesh>
          </geometry>
          <material>
            <script>
              <uri>model://pine_tree/materials/scripts/</uri>
              <uri>model://pine_tree/materials/textures/</uri>
              <name>PineTree/Bark</name>
            </script>
          </material>
        </visual>
        <self_collide>0</self_collide>
        <kinematic>0</kinematic>
      </link>
      <pose frame=''>-0.464776 -8.61157 0 0 -0 0</pose>
    </model>
    <model name='pine_tree_clone'>
      <static>1</static>
      <link name='link'>
        <collision name='collision'>
          <geometry>
            <mesh>
              <uri>model://pine_tree/meshes/pine_tree.dae</uri>
            </mesh>
          </geometry>
          <max_contacts>10</max_contacts>
          <surface>
            <contact>
              <ode/>
            </contact>
            <bounce/>
            <friction>
              <torsional>
                <ode/>
              </torsional>
              <ode/>
            </friction>
          </surface>
        </collision>
        <visual name='branch'>
          <geometry>
            <mesh>
              <uri>model://pine_tree/meshes/pine_tree.dae</uri>
              <submesh>
                <name>Branch</name>
              </submesh>
            </mesh>
          </geometry>
          <material>
            <script>
              <uri>model://pine_tree/materials/scripts/</uri>
              <uri>model://pine_tree/materials/textures/</uri>
              <name>PineTree/Branch</name>
            </script>
          </material>
        </visual>
        <visual name='bark'>
          <geometry>
            <mesh>
              <uri>model://pine_tree/meshes/pine_tree.dae</uri>
              <submesh>
                <name>Bark</name>
              </submesh>
            </mesh>
          </geometry>
          <material>
            <script>
              <uri>model://pine_tree/materials/scripts/</uri>
              <uri>model://pine_tree/materials/textures/</uri>
              <name>PineTree/Bark</name>
            </script>
          </material>
        </visual>
        <self_collide>0</self_collide>
        <kinematic>0</kinematic>
      </link>
      <pose frame=''>2.02707 -8.6411 0 0 -0 0</pose>
    </model>
    <model name='pine_tree_clone_0'>
      <static>1</static>
      <link name='link'>
        <collision name='collision'>
          <geometry>
            <mesh>
              <uri>model://pine_tree/meshes/pine_tree.dae</uri>
            </mesh>
          </geometry>
          <max_contacts>10</max_contacts>
          <surface>
            <contact>
              <ode/>
            </contact>
            <bounce/>
            <friction>
              <torsional>
                <ode/>
              </torsional>
              <ode/>
            </friction>
          </surface>
        </collision>
        <visual name='branch'>
          <geometry>
            <mesh>
              <uri>model://pine_tree/meshes/pine_tree.dae</uri>
              <submesh>
                <name>Branch</name>
              </submesh>
            </mesh>
          </geometry>
          <material>
            <script>
              <uri>model://pine_tree/materials/scripts/</uri>
              <uri>model://pine_tree/materials/textures/</uri>
              <name>PineTree/Branch</name>
            </script>
          </material>
        </visual>
        <visual name='bark'>
          <geometry>
            <mesh>
              <uri>model://pine_tree/meshes/pine_tree.dae</uri>
              <submesh>
                <name>Bark</name>
              </submesh>
            </mesh>
          </geometry>
          <material>
            <script>
              <uri>model://pine_tree/materials/scripts/</uri>
              <uri>model://pine_tree/materials/textures/</uri>
              <name>PineTree/Bark</name>
            </script>
          </material>
        </visual>
        <self_collide>0</self_collide>
        <kinematic>0</kinematic>
      </link>
      <pose frame=''>4.45448 -8.58842 0 0 -0 0</pose>
    </model>
    <model name='table_marble'>
      <static>1</static>
      <pose frame=''>1.32313 -2.36304 0.648 0 -0 0</pose>
      <link name='link'>
        <collision name='collision'>
          <geometry>
            <mesh>
              <uri>model:///table_marble/meshes/table_lightmap.dae</uri>
              <scale>0.25 0.25 0.25</scale>
            </mesh>
          </geometry>
          <max_contacts>10</max_contacts>
          <surface>
            <contact>
              <ode/>
            </contact>
            <bounce/>
            <friction>
              <torsional>
                <ode/>
              </torsional>
              <ode/>
            </friction>
          </surface>
        </collision>
        <visual name='visual'>
          <geometry>
            <mesh>
              <uri>model://table_marble/meshes/table_lightmap.dae</uri>
              <scale>0.25 0.25 0.25</scale>
            </mesh>
          </geometry>
          <material>
            <script>
              <uri>model://table_marble/materials/scripts</uri>
              <uri>model://table_marble/materials/textures</uri>
              <name>Table/Marble_Lightmap</name>
            </script>
            <lighting>0</lighting>
          </material>
        </visual>
        <self_collide>0</self_collide>
        <kinematic>0</kinematic>
      </link>
    </model>
    <model name='unit_cylinder'>
      <link name='link'>
        <pose frame=''>0 0 0 0 -0 0</pose>
        <inertial>
          <mass>1</mass>
          <inertia>
            <ixx>0.145833</ixx>
            <ixy>0</ixy>
            <ixz>0</ixz>
            <iyy>0.145833</iyy>
            <iyz>0</iyz>
            <izz>0.125</izz>
          </inertia>
          <pose frame=''>0 0 0 0 -0 0</pose>
        </inertial>
        <self_collide>0</self_collide>
        <kinematic>0</kinematic>
        <gravity>1</gravity>
        <visual name='visual'>
          <geometry>
            <cylinder>
              <radius>0.5</radius>
              <length>1.3</length>
            </cylinder>
          </geometry>
          <material>
            <script>
              <name>Gazebo/Grey</name>
              <uri>file://media/materials/scripts/gazebo.material</uri>
            </script>
            <shader type='pixel'>
              <normal_map>__default__</normal_map>
            </shader>
            <ambient>0.5 0.3 0.3 1</ambient>
            <diffuse>0.9 0.7 0.7 1</diffuse>
            <specular>0.01 0.01 0.01 1</specular>
            <emissive>0 0 0 1</emissive>
          </material>
          <pose frame=''>0 0 0 0 -0 0</pose>
          <transparency>0</transparency>
          <cast_shadows>1</cast_shadows>
        </visual>
        <collision name='collision'>
          <laser_retro>0</laser_retro>
          <max_contacts>10</max_contacts>
          <pose frame=''>0 0 0 0 -0 0</pose>
          <geometry>
            <cylinder>
              <radius>0.5</radius>
              <length>1.3</length>
            </cylinder>
          </geometry>
          <surface>
            <friction>
              <ode>
                <mu>1</mu>
                <mu2>1</mu2>
                <fdir1>0 0 0</fdir1>
                <slip1>0</slip1>
                <slip2>0</slip2>
              </ode>
              <torsional>
                <coefficient>1</coefficient>
                <patch_radius>0</patch_radius>
                <surface_radius>0</surface_radius>
                <use_patch_radius>1</use_patch_radius>
                <ode>
                  <slip>0</slip>
                </ode>
              </torsional>
            </friction>
            <bounce>
              <restitution_coefficient>0</restitution_coefficient>
              <threshold>1e+06</threshold>
            </bounce>
            <contact>
              <collide_without_contact>0</collide_without_contact>
              <collide_without_contact_bitmask>1</collide_without_contact_bitmask>
              <collide_bitmask>1</collide_bitmask>
              <ode>
                <soft_cfm>0</soft_cfm>
                <soft_erp>0.2</soft_erp>
                <kp>1e+13</kp>
                <kd>1</kd>
                <max_vel>0.01</max_vel>
                <min_depth>0</min_depth>
              </ode>
              <bullet>
                <split_impulse>1</split_impulse>
                <split_impulse_penetration_threshold>-0.01</split_impulse_penetration_threshold>
                <soft_cfm>0</soft_cfm>
                <soft_erp>0.2</soft_erp>
                <kp>1e+13</kp>
                <kd>1</kd>
              </bullet>
            </contact>
          </surface>
        </collision>
      </link>
      <static>0</static>
      <allow_auto_disable>1</allow_auto_disable>
      <pose frame=''>-2.00044 2.55114 0.5 0 -0 0</pose>
    </model>
    <gui fullscreen='0'>
      <camera name='user_camera'>
        <pose frame=''>1.56277 -3.27605 2.34728 0 0.965796 0.677793</pose>
        <view_controller>ortho</view_controller>
        <projection_type>orthographic</projection_type>
      </camera>
    </gui>
    <model name='person_walking_clone_clone'>
      <link name='link'>
        <inertial>
          <pose frame=''>0 0 0.95 0 -0 0</pose>
          <mass>80</mass>
          <inertia>
            <ixx>27.82</ixx>
            <ixy>0</ixy>
            <ixz>0</ixz>
            <iyy>24.88</iyy>
            <iyz>0</iyz>
            <izz>4.57</izz>
          </inertia>
        </inertial>
        <collision name='bottom'>
          <pose frame=''>0 0 0.01 0 -0 0</pose>
          <geometry>
            <box>
              <size>0.35 0.75 0.02</size>
            </box>
          </geometry>
          <max_contacts>10</max_contacts>
          <surface>
            <contact>
              <ode/>
            </contact>
            <bounce/>
            <friction>
              <torsional>
                <ode/>
              </torsional>
              <ode/>
            </friction>
          </surface>
        </collision>
        <collision name='person'>
          <pose frame=''>0 0 -0.02 0 -0 0</pose>
          <geometry>
            <mesh>
              <uri>model://person_walking/meshes/walking.dae</uri>
            </mesh>
          </geometry>
          <max_contacts>10</max_contacts>
          <surface>
            <contact>
              <ode/>
            </contact>
            <bounce/>
            <friction>
              <torsional>
                <ode/>
              </torsional>
              <ode/>
            </friction>
          </surface>
        </collision>
        <visual name='visual'>
          <pose frame=''>0 0 -0.02 0 -0 0</pose>
          <geometry>
            <mesh>
              <uri>model://person_walking/meshes/walking.dae</uri>
            </mesh>
          </geometry>
        </visual>
        <self_collide>0</self_collide>
        <kinematic>0</kinematic>
      </link>
      <pose frame=''>2.60307 -7.48959 1e-06 1e-06 -1e-06 -1.56678</pose>
    </model>
  </world>
</sdf>
